Workbook

Sheet 그래프 분석
B1: S&P500 | C1: KOSPI200 | D1: s&p500 nor | E1: KOSPI200 nor
A2: 39449 | B2: 1447.16 | C2: 235.3 | D2: =B2*100/B$2 -> 100 | E2: =C2*100/C$2 -> 100 | F2: 회귀
A3: 39450 | B3: 1447.16 | C3: 234.67 | D3: =B3*100/B$2 -> 100 | E3: =C3*100/C$2 -> 99.732257 | F3: 회귀 모델 | G3: 선형
A4: 39451 | B4: 1411.63 | C4: 235.77 | D4: =B4*100/B$2 -> 97.544846 | E4: =C4*100/C$2 -> 100.19975
A5: 39454 | B5: 1416.18 | C5: 231 | D5: =B5*100/B$2 -> 97.859255 | E5: =C5*100/C$2 -> 98.172546 | F5: LINEST raw output
A6: 39455 | B6: 1390.19 | C6: 230.34 | D6: =B6*100/B$2 -> 96.063324 | E6: =C6*100/C$2 -> 97.892053 | F6: {=LINEST($E$2:$E$2593 , $D$2:$D$2593 , 1 , 1)} -> 0.33404021 | G6: 66.430682
A7: 39456 | B7: 1409.13 | C7: 232.53 | D7: =B7*100/B$2 -> 97.372094 | E7: =C7*100/C$2 -> 98.822779 | F7: 0.0062853151 | G7: 0.73113575
A8: 39457 | B8: 1420.33 | C8: 229.47 | D8: =B8*100/B$2 -> 98.146024 | E8: =C8*100/C$2 -> 97.522312 | F8: 0.52165586 | G8: 10.660444
A9: 39458 | B9: 1401.02 | C9: 224.41 | D9: =B9*100/B$2 -> 96.811686 | E9: =C9*100/C$2 -> 95.371866 | F9: 2824.5119 | G9: 2590
A10: 39461 | B10: 1416.25 | C10: 222.81 | D10: =B10*100/B$2 -> 97.864092 | E10: =C10*100/C$2 -> 94.691883 | F10: 320991.81 | G10: 294340.7
A11: 39462 | B11: 1380.95 | C11: 220.91 | D11: =B11*100/B$2 -> 95.424832 | E11: =C11*100/C$2 -> 93.884403
A12: 39463 | B12: 1373.2 | C12: 215.87 | D12: =B12*100/B$2 -> 94.8893 | E12: =C12*100/C$2 -> 91.742456 | F12: Regression Statistics
A13: 39464 | B13: 1333.25 | C13: 218.83 | D13: =B13*100/B$2 -> 92.128721 | E13: =C13*100/C$2 -> 93.000425 | F13: R^2 | G13: =$F$8 -> 0.52165586
A14: 39465 | B14: 1325.19 | C14: 219.87 | D14: =B14*100/B$2 -> 91.571768 | E14: =C14*100/C$2 -> 93.442414 | F14: 표준 오류 | G14: =$G$8 -> 10.660444
A15: 39468 | B15: 1325.19 | C15: 213.6 | D15: =B15*100/B$2 -> 91.571768 | E15: =C15*100/C$2 -> 90.777731 | F15: Count of X variables | G15: =1 -> 1
A16: 39469 | B16: 1310.5 | C16: 204.55 | D16: =B16*100/B$2 -> 90.556677 | E16: =C16*100/C$2 -> 86.931577 | F16: 관찰 | G16: =2592 -> 2592
A17: 39470 | B17: 1338.6 | C17: 207.23 | D17: =B17*100/B$2 -> 92.498411 | E17: =C17*100/C$2 -> 88.070548 | F17: Adjusted R^2 | G17: =1 - (1 - $F$8)*($G$16 - 1)/($G$16 - $G$15 - 1) -> 0.52147117
A18: 39471 | B18: 1352.07 | C18: 211.2 | D18: =B18*100/B$2 -> 93.429199 | E18: =C18*100/C$2 -> 89.757756
A19: 39472 | B19: 1330.61 | C19: 215.06 | D19: =B19*100/B$2 -> 91.946295 | E19: =C19*100/C$2 -> 91.398215 | F19: Analysis of Variance (ANOVA)
A20: 39475 | B20: 1353.96 | C20: 206.52 | D20: =B20*100/B$2 -> 93.5598 | E20: =C20*100/C$2 -> 87.768806 | G20: df | H20: SS | I20: MS | J20: F | K20: Significance F
A21: 39476 | B21: 1362.3 | C21: 208.8 | D21: =B21*100/B$2 -> 94.136101 | E21: =C21*100/C$2 -> 88.737782 | F21: 회귀 | G21: =$G$15 -> 1 | H21: =$F$10 -> 320991.81 | I21: =$F$10 / $G$21 -> 320991.81 | J21: =$F$9 -> 2824.5119 | K21: =FDIST($F$9 , $G$21 , $G$9) -> 0
A22: 39477 | B22: 1355.81 | C22: 203.5 | D22: =B22*100/B$2 -> 93.687636 | E22: =C22*100/C$2 -> 86.485338 | F22: Residual | G22: =$G$9 -> 2590 | H22: =$G$10 -> 294340.7 | I22: =$G$10 / $G$9 -> 113.64506
A23: 39478 | B23: 1378.55 | C23: 207.77 | D23: =B23*100/B$2 -> 95.25899 | E23: =C23*100/C$2 -> 88.300042 | F23: 전체 | G23: =$G$21 + $G$9 -> 2591 | H23: =$F$10 + $G$10 -> 615332.51
A24: 39479 | B24: 1395.42 | C24: 209.08 | D24: =B24*100/B$2 -> 96.424722 | E24: =C24*100/C$2 -> 88.856779
A25: 39482 | B25: 1380.82 | C25: 216.23 | D25: =B25*100/B$2 -> 95.415849 | E25: =C25*100/C$2 -> 91.895453 | F25: Confidence level | G25: 0.95
A26: 39483 | B26: 1336.64 | C26: 216.91 | D26: =B26*100/B$2 -> 92.362973 | E26: =C26*100/C$2 -> 92.184445
A27: 39484 | B27: 1326.45 | C27: 216.91 | D27: =B27*100/B$2 -> 91.658835 | E27: =C27*100/C$2 -> 92.184445 | G27: Coefficients | H27: 표준 오류 | I27: t-Statistic | J27: P-값 | K27: =_xlfn.CONCAT("Lower " , INT($G$25 * 100) , "%") -> Lower 95% | L27: =_xlfn.CONCAT("Upper " , INT($G$25 * 100) , "%") -> Upper 95%
A28: 39485 | B28: 1336.91 | C28: 216.91 | D28: =B28*100/B$2 -> 92.38163 | E28: =C28*100/C$2 -> 92.184445 | F28: ="가로챔" -> 가로챔 | G28: {=INDEX($F$6:$G$6, 1 , 30 - ROW())} -> 66.430682 | H28: {=INDEX($F$7:$G$7, 1 , 30 - ROW())} -> 0.73113575 | I28: {=$G$28:$G$29 / $H$28:$H$29} -> 90.859572 | J28: {=TDIST(ABS($I$28:$I$29) , $G$9 , 2 )} -> 0 | K28: {=$G$28:$G$29 - $H$28:$H$29 * TINV(1 - $G$25 , $G$9)} -> 64.997012 | L28: {=$G$28:$G$29 + $H$28:$H$29 * TINV(1 - $G$25 , $G$9)} -> 67.864351
A29: 39486 | B29: 1331.29 | C29: 216.91 | D29: =B29*100/B$2 -> 91.993283 | E29: =C29*100/C$2 -> 92.184445 | F29: ="X1" -> X1 | G29: 0.33404021 | H29: 0.0062853151 | I29: 53.146137 | J29: 0 | K29: 0.32171546 | L29: 0.34636496
A30: 39489 | B30: 1339.13 | C30: 208.92 | D30: =B30*100/B$2 -> 92.535034 | E30: =C30*100/C$2 -> 88.78878
A31: 39490 | B31: 1348.86 | C31: 209.01 | D31: =B31*100/B$2 -> 93.207385 | E31: =C31*100/C$2 -> 88.827029 | F31: ="X1" -> X1 | G31: Predicted Y | H31: ="Y" -> Y | I31: Residual
A32: 39491 | B32: 1367.21 | C32: 207.56 | D32: =B32*100/B$2 -> 94.475386 | E32: =C32*100/C$2 -> 88.210795 | F32: {=$D$2:$D$2593} -> 100 | G32: {=MMULT($F$32:$F$2623 , $G$29) + $G$28} -> 99.834703 | H32: {=$E$2:$E$2593} -> 100 | I32: {=$H$32:$H$2623 - $G$32:$G$2623} -> 0.16529694
A33: 39492 | B33: 1348.86 | C33: 216.2 | D33: =B33*100/B$2 -> 93.207385 | E33: =C33*100/C$2 -> 91.882703 | F33: 100 | G33: 99.834703 | H33: 99.732257 | I33: -0.10244636
A34: 39493 | B34: 1349.99 | C34: 215.38 | D34: =B34*100/B$2 -> 93.285469 | E34: =C34*100/C$2 -> 91.534212 | F34: 97.544846 | G34: 99.014583 | H34: 100.19975 | I34: 1.185162
A35: 39496 | B35: 1349.99 | C35: 215.46 | D35: =B35*100/B$2 -> 93.285469 | E35: =C35*100/C$2 -> 91.568211 | F35: 97.859255 | G35: 99.119608 | H35: 98.172546 | I35: -0.94706258
A36: 39497 | B36: 1348.78 | C36: 218.37 | D36: =B36*100/B$2 -> 93.201857 | E36: =C36*100/C$2 -> 92.80493 | F36: 96.063324 | G36: 98.519695 | H36: 97.892053 | I36: -0.62764228
A37: 39498 | B37: 1360.03 | C37: 213.84 | D37: =B37*100/B$2 -> 93.979242 | E37: =C37*100/C$2 -> 90.879728 | F37: 97.372094 | G37: 98.956877 | H37: 98.822779 | I37: -0.13409745
A38: 39499 | B38: 1342.53 | C38: 216.38 | D38: =B38*100/B$2 -> 92.769977 | E38: =C38*100/C$2 -> 91.959201 | F38: 98.146024 | G38: 99.2154 | H38: 97.522312 | I38: -1.6930886
A39: 39500 | B39: 1353.11 | C39: 213.73 | D39: =B39*100/B$2 -> 93.501064 | E39: =C39*100/C$2 -> 90.832979 | F39: 96.811686 | G39: 98.769678 | H39: 95.371866 | I39: -3.3978124
A40: 39503 | B40: 1371.8 | C40: 217.07 | D40: =B40*100/B$2 -> 94.792559 | E40: =C40*100/C$2 -> 92.252444 | F40: 97.864092 | G40: 99.121224 | H40: 94.691883 | I40: -4.4293413
...

Sheet 종목 기본정보
A1: 종목명 | B1: A전자 | C1: B건설 | D1: C증권 | E1: D화학 | F1: E엔터
A2: 상장주식수 | B2: 10000000 | C2: 5000000 | D2: 20000000 | E2: 1000000 | F2: 1000000

Sheet 일자별 주가
A1: 일자 | B1: A전자 | C1: B건설 | D1: C증권 | E1: D화학 | F1: E엔터
A2: 1 | B2: 10000 | C2: 20000 | D2: 30000 | E2: 100000 | F2: 1000000
A3: 2 | B3: =RANDBETWEEN(B2*0.97,B2*1.033) -> 9945 | C3: =RANDBETWEEN(C2*0.97,C2*1.033) -> 19486 | D3: =RANDBETWEEN(D2*0.97,D2*1.033) -> 29650 | E3: =RANDBETWEEN(E2*0.97,E2*1.033) -> 99269 | F3: =RANDBETWEEN(F2*0.97,F2*1.033) -> 1002417
A4: 3 | B4: =RANDBETWEEN(B3*0.97,B3*1.033) -> 10112 | C4: =RANDBETWEEN(C3*0.97,C3*1.033) -> 19818 | D4: =RANDBETWEEN(D3*0.97,D3*1.033) -> 29756 | E4: =RANDBETWEEN(E3*0.97,E3*1.033) -> 100443 | F4: =RANDBETWEEN(F3*0.97,F3*1.033) -> 982924
A5: 4 | B5: =RANDBETWEEN(B4*0.97,B4*1.033) -> 9885 | C5: =RANDBETWEEN(C4*0.97,C4*1.033) -> 20246 | D5: =RANDBETWEEN(D4*0.97,D4*1.033) -> 30292 | E5: =RANDBETWEEN(E4*0.97,E4*1.033) -> 100388 | F5: =RANDBETWEEN(F4*0.97,F4*1.033) -> 1012472
A6: 5 | B6: =RANDBETWEEN(B5*0.97,B5*1.033) -> 9823 | C6: =RANDBETWEEN(C5*0.97,C5*1.033) -> 20634 | D6: =RANDBETWEEN(D5*0.97,D5*1.033) -> 30171 | E6: =RANDBETWEEN(E5*0.97,E5*1.033) -> 101056 | F6: =RANDBETWEEN(F5*0.97,F5*1.033) -> 994912
A7: 6 | B7: =RANDBETWEEN(B6*0.97,B6*1.033) -> 9822 | C7: =RANDBETWEEN(C6*0.97,C6*1.033) -> 21114 | D7: =RANDBETWEEN(D6*0.97,D6*1.033) -> 31036 | E7: =RANDBETWEEN(E6*0.97,E6*1.033) -> 103996 | F7: =RANDBETWEEN(F6*0.97,F6*1.033) -> 985374
A8: 7 | B8: =RANDBETWEEN(B7*0.97,B7*1.033) -> 9596 | C8: =RANDBETWEEN(C7*0.97,C7*1.033) -> 21415 | D8: =RANDBETWEEN(D7*0.97,D7*1.033) -> 30370 | E8: =RANDBETWEEN(E7*0.97,E7*1.033) -> 106378 | F8: =RANDBETWEEN(F7*0.97,F7*1.033) -> 1007167
A9: 8 | B9: =RANDBETWEEN(B8*0.97,B8*1.033) -> 9477 | C9: =RANDBETWEEN(C8*0.97,C8*1.033) -> 21502 | D9: =RANDBETWEEN(D8*0.97,D8*1.033) -> 29702 | E9: =RANDBETWEEN(E8*0.97,E8*1.033) -> 104658 | F9: =RANDBETWEEN(F8*0.97,F8*1.033) -> 1034284
A10: 9 | B10: =RANDBETWEEN(B9*0.97,B9*1.033) -> 9697 | C10: =RANDBETWEEN(C9*0.97,C9*1.033) -> 21082 | D10: =RANDBETWEEN(D9*0.97,D9*1.033) -> 29250 | E10: =RANDBETWEEN(E9*0.97,E9*1.033) -> 105395 | F10: =RANDBETWEEN(F9*0.97,F9*1.033) -> 1046768
A11: 10 | B11: =RANDBETWEEN(B10*0.97,B10*1.033) -> 9694 | C11: =RANDBETWEEN(C10*0.97,C10*1.033) -> 21043 | D11: =RANDBETWEEN(D10*0.97,D10*1.033) -> 29156 | E11: =RANDBETWEEN(E10*0.97,E10*1.033) -> 107106 | F11: =RANDBETWEEN(F10*0.97,F10*1.033) -> 1061015
A12: 11 | B12: =RANDBETWEEN(B11*0.97,B11*1.033) -> 9910 | C12: =RANDBETWEEN(C11*0.97,C11*1.033) -> 21246 | D12: =RANDBETWEEN(D11*0.97,D11*1.033) -> 29110 | E12: =RANDBETWEEN(E11*0.97,E11*1.033) -> 109881 | F12: =RANDBETWEEN(F11*0.97,F11*1.033) -> 1074420
A13: 12 | B13: =RANDBETWEEN(B12*0.97,B12*1.033) -> 9887 | C13: =RANDBETWEEN(C12*0.97,C12*1.033) -> 21218 | D13: =RANDBETWEEN(D12*0.97,D12*1.033) -> 28699 | E13: =RANDBETWEEN(E12*0.97,E12*1.033) -> 109750 | F13: =RANDBETWEEN(F12*0.97,F12*1.033) -> 1065459
A14: 13 | B14: =RANDBETWEEN(B13*0.97,B13*1.033) -> 10008 | C14: =RANDBETWEEN(C13*0.97,C13*1.033) -> 21012 | D14: =RANDBETWEEN(D13*0.97,D13*1.033) -> 29646 | E14: =RANDBETWEEN(E13*0.97,E13*1.033) -> 107235 | F14: =RANDBETWEEN(F13*0.97,F13*1.033) -> 1081999
... A366: 365 | B366: =RANDBETWEEN(B365*0.97,B365*1.033) -> 17374 | C366: =RANDBETWEEN(C365*0.97,C365*1.033) -> 28014 | D366: =RANDBETWEEN(D365*0.97,D365*1.033) -> 74930 | E366: =RANDBETWEEN(E365*0.97,E365*1.033) -> 110410 | F366: =RANDBETWEEN(F365*0.97,F365*1.033) -> 2824748

Sheet 일자별 시가총액
A1: 일자 | B1: A전자 | C1: B건설 | D1: C증권 | E1: D화학 | F1: E엔터 | G1: 합계 | H1: 지수
A2: 1 | B2: ='종목 기본정보'!B$2*'일자별 주가'!B2 -> 100000000000 | C2: ='종목 기본정보'!C$2*'일자별 주가'!C2 -> 100000000000 | D2: ='종목 기본정보'!D$2*'일자별 주가'!D2 -> 600000000000 | E2: ='종목 기본정보'!E$2*'일자별 주가'!E2 -> 100000000000 | F2: ='종목 기본정보'!F$2*'일자별 주가'!F2 -> 1000000000000 | G2: =SUM(B2:F2) -> 1900000000000 | H2: =G2*100/G$2 -> 100
A3: 2 | B3: ='종목 기본정보'!B$2*'일자별 주가'!B3 -> 99450000000 | C3: ='종목 기본정보'!C$2*'일자별 주가'!C3 -> 97430000000 | D3: ='종목 기본정보'!D$2*'일자별 주가'!D3 -> 593000000000 | E3: ='종목 기본정보'!E$2*'일자별 주가'!E3 -> 99269000000 | F3: ='종목 기본정보'!F$2*'일자별 주가'!F3 -> 1002417000000 | G3: =SUM(B3:F3) -> 1891566000000 | H3: =G3*100/G$2 -> 99.556105
A4: 3 | B4: ='종목 기본정보'!B$2*'일자별 주가'!B4 -> 101120000000 | C4: ='종목 기본정보'!C$2*'일자별 주가'!C4 -> 99090000000 | D4: ='종목 기본정보'!D$2*'일자별 주가'!D4 -> 595120000000 | E4: ='종목 기본정보'!E$2*'일자별 주가'!E4 -> 100443000000 | F4: ='종목 기본정보'!F$2*'일자별 주가'!F4 -> 982924000000 | G4: =SUM(B4:F4) -> 1878697000000 | H4: =G4*100/G$2 -> 98.878789
A5: 4 | B5: ='종목 기본정보'!B$2*'일자별 주가'!B5 -> 98850000000 | C5: ='종목 기본정보'!C$2*'일자별 주가'!C5 -> 101230000000 | D5: ='종목 기본정보'!D$2*'일자별 주가'!D5 -> 605840000000 | E5: ='종목 기본정보'!E$2*'일자별 주가'!E5 -> 100388000000 | F5: ='종목 기본정보'!F$2*'일자별 주가'!F5 -> 1012472000000 | G5: =SUM(B5:F5) -> 1918780000000 | H5: =G5*100/G$2 -> 100.98842
A6: 5 | B6: ='종목 기본정보'!B$2*'일자별 주가'!B6 -> 98230000000 | C6: ='종목 기본정보'!C$2*'일자별 주가'!C6 -> 103170000000 | D6: ='종목 기본정보'!D$2*'일자별 주가'!D6 -> 603420000000 | E6: ='종목 기본정보'!E$2*'일자별 주가'!E6 -> 101056000000 | F6: ='종목 기본정보'!F$2*'일자별 주가'!F6 -> 994912000000 | G6: =SUM(B6:F6) -> 1900788000000 | H6: =G6*100/G$2 -> 100.04147
A7: 6 | B7: ='종목 기본정보'!B$2*'일자별 주가'!B7 -> 98220000000 | C7: ='종목 기본정보'!C$2*'일자별 주가'!C7 -> 105570000000 | D7: ='종목 기본정보'!D$2*'일자별 주가'!D7 -> 620720000000 | E7: ='종목 기본정보'!E$2*'일자별 주가'!E7 -> 103996000000 | F7: ='종목 기본정보'!F$2*'일자별 주가'!F7 -> 985374000000 | G7: =SUM(B7:F7) -> 1913880000000 | H7: =G7*100/G$2 -> 100.73053
A8: 7 | B8: ='종목 기본정보'!B$2*'일자별 주가'!B8 -> 95960000000 | C8: ='종목 기본정보'!C$2*'일자별 주가'!C8 -> 107075000000 | D8: ='종목 기본정보'!D$2*'일자별 주가'!D8 -> 607400000000 | E8: ='종목 기본정보'!E$2*'일자별 주가'!E8 -> 106378000000 | F8: ='종목 기본정보'!F$2*'일자별 주가'!F8 -> 1007167000000 | G8: =SUM(B8:F8) -> 1923980000000 | H8: =G8*100/G$2 -> 101.26211
A9: 8 | B9: ='종목 기본정보'!B$2*'일자별 주가'!B9 -> 94770000000 | C9: ='종목 기본정보'!C$2*'일자별 주가'!C9 -> 107510000000 | D9: ='종목 기본정보'!D$2*'일자별 주가'!D9 -> 594040000000 | E9: ='종목 기본정보'!E$2*'일자별 주가'!E9 -> 104658000000 | F9: ='종목 기본정보'!F$2*'일자별 주가'!F9 -> 1034284000000 | G9: =SUM(B9:F9) -> 1935262000000 | H9: =G9*100/G$2 -> 101.85589
A10: 9 | B10: ='종목 기본정보'!B$2*'일자별 주가'!B10 -> 96970000000 | C10: ='종목 기본정보'!C$2*'일자별 주가'!C10 -> 105410000000 | D10: ='종목 기본정보'!D$2*'일자별 주가'!D10 -> 585000000000 | E10: ='종목 기본정보'!E$2*'일자별 주가'!E10 -> 105395000000 | F10: ='종목 기본정보'!F$2*'일자별 주가'!F10 -> 1046768000000 | G10: =SUM(B10:F10) -> 1939543000000 | H10: =G10*100/G$2 -> 102.08121
A11: 10 | B11: ='종목 기본정보'!B$2*'일자별 주가'!B11 -> 96940000000 | C11: ='종목 기본정보'!C$2*'일자별 주가'!C11 -> 105215000000 | D11: ='종목 기본정보'!D$2*'일자별 주가'!D11 -> 583120000000 | E11: ='종목 기본정보'!E$2*'일자별 주가'!E11 -> 107106000000 | F11: ='종목 기본정보'!F$2*'일자별 주가'!F11 -> 1061015000000 | G11: =SUM(B11:F11) -> 1953396000000 | H11: =G11*100/G$2 -> 102.81032
A12: 11 | B12: ='종목 기본정보'!B$2*'일자별 주가'!B12 -> 99100000000 | C12: ='종목 기본정보'!C$2*'일자별 주가'!C12 -> 106230000000 | D12: ='종목 기본정보'!D$2*'일자별 주가'!D12 -> 582200000000 | E12: ='종목 기본정보'!E$2*'일자별 주가'!E12 -> 109881000000 | F12: ='종목 기본정보'!F$2*'일자별 주가'!F12 -> 1074420000000 | G12: =SUM(B12:F12) -> 1971831000000 | H12: =G12*100/G$2 -> 103.78058
A13: 12 | B13: ='종목 기본정보'!B$2*'일자별 주가'!B13 -> 98870000000 | C13: ='종목 기본정보'!C$2*'일자별 주가'!C13 -> 106090000000 | D13: ='종목 기본정보'!D$2*'일자별 주가'!D13 -> 573980000000 | E13: ='종목 기본정보'!E$2*'일자별 주가'!E13 -> 109750000000 | F13: ='종목 기본정보'!F$2*'일자별 주가'!F13 -> 1065459000000 | G13: =SUM(B13:F13) -> 1954149000000 | H13: =G13*100/G$2 -> 102.84995
... A366: 365 | B366: ='종목 기본정보'!B$2*'일자별 주가'!B366 -> 173740000000 | C366: ='종목 기본정보'!C$2*'일자별 주가'!C366 -> 140070000000 | D366: ='종목 기본정보'!D$2*'일자별 주가'!D366 -> 1498600000000 | E366: ='종목 기본정보'!E$2*'일자별 주가'!E366 -> 110410000000 | F366: ='종목 기본정보'!F$2*'일자별 주가'!F366 -> 2824748000000 | G366: =SUM(B366:F366) -> 4747568000000 | H366: =G366*100/G$2 -> 249.872
